Workbook

Sheet Props Tracker
A1: ⚾ Analytic Overview — Daily Props Tracker
A2: Fill in Result columns after games: 1 = hit, 0 = miss. P&L auto-calculates. Odds columns use American format (e.g. +550, -110).
A3: Date | B3: Player | C3: Team | D3: Score | E3: vs Pitcher | F3: HR Odds | G3: 2H Odds | H3: 3H Odds | I3: HR Result | J3: 2H Result | K3: 3H Result | L3: HR P&L ($) | M3: 2H P&L ($) | N3: 3H P&L ($) | O3: Day P&L ($) | P3: Average HR odds | Q3: Average 2H Odds | R3: Average 3H Odds | S3: HR Profit | T3: 2H profit | U3: 3H profit | V3: 1H Odds | W3: 1H Result | X3: 1H P&L ($) | Y3: Average 1H Odds | Z3: 1H break-even
A4: 2026-08-13 ← example row | B4: Yordan Alvarez | C4: HOU | D4: 186 | E4: vs R. Gilbert (R) | F4: +480 | G4: +210 | H4: +950 | L4: =IFERROR(IF(I4="","",IF(I4=1,IF(F4>0,F4/100,100/ABS(F4)),-1)),"") | M4: =IFERROR(IF(J4="","",IF(J4=1,IF(G4>0,G4/100,100/ABS(G4)),-1)),"") | N4: =IFERROR(IF(K4="","",IF(K4=1,IF(H4>0,H4/100,100/ABS(H4)),-1)),"") | O4: =IF(COUNT(I4,J4,K4,W4)=0,"",SUM(L4,M4,N4,X4)) | P4: =AVERAGE(F5:F400) -> 487.66667 | Q4: =AVERAGE(G5:G400) -> 245.55556 | R4: =AVERAGE(H5:H400) -> 1161.1111 | S4: =(1/((P4/100)+1))*100 -> 17.016449 | T4: =(1/((Q4/100)+1))*100 -> 28.938907 | U4: =(1/((R4/100)+1))*100 -> 7.9295154 | V4: -165 | X4: =IFERROR(IF(W4="","",IF(W4=1,IF(V4>0,V4/100,100/ABS(V4)),-1)),"") | Y4: =IFERROR(AVERAGE(V5:V400),0) -> -231.73333 | Z4: =IF(Y4=0,"",IF(Y4>0,(1/((Y4/100)+1))*100,(ABS(Y4)/(ABS(Y4)+100))*100)) -> 69.855305
A5: 46259 | B5: Bryce Harper | C5: PHI | D5: 172.6 | F5: 481 | G5: 276 | H5: 1360 | I5: 0 | J5: 1 | K5: 0 | L5: =IFERROR(IF(I5="","",IF(I5=1,IF(F5>0,F5/100,100/ABS(F5)),-1)),"") -> -1 | M5: =IFERROR(IF(J5="","",IF(J5=1,IF(G5>0,G5/100,100/ABS(G5)),-1)),"") -> 2.76 | N5: =IFERROR(IF(K5="","",IF(K5=1,IF(H5>0,H5/100,100/ABS(H5)),-1)),"") -> -1 | O5: =IF(COUNT(I5,J5,K5,W5)=0,"",SUM(L5,M5,N5,X5)) -> 1.2575124 | V5: -201 | W5: 1 | X5: =IFERROR(IF(W5="","",IF(W5=1,IF(V5>0,V5/100,100/ABS(V5)),-1)),"") -> 0.49751244
A6: 46259 | B6: Alec Burleson | C6: STL | D6: 162.3 | F6: 535 | G6: 169 | H6: 780 | I6: 0 | J6: 0 | K6: 0 | L6: =IFERROR(IF(I6="","",IF(I6=1,IF(F6>0,F6/100,100/ABS(F6)),-1)),"") -> -1 | M6: =IFERROR(IF(J6="","",IF(J6=1,IF(G6>0,G6/100,100/ABS(G6)),-1)),"") -> -1 | N6: =IFERROR(IF(K6="","",IF(K6=1,IF(H6>0,H6/100,100/ABS(H6)),-1)),"") -> -1 | O6: =IF(COUNT(I6,J6,K6,W6)=0,"",SUM(L6,M6,N6,X6)) -> -2.6996997 | V6: -333 | W6: 1 | X6: =IFERROR(IF(W6="","",IF(W6=1,IF(V6>0,V6/100,100/ABS(V6)),-1)),"") -> 0.3003003
A7: 46259 | B7: Yandy Diaz | C7: TBR | D7: 160.2 | F7: 810 | G7: 190 | H7: 850 | I7: 0 | J7: 0 | K7: 0 | L7: =IFERROR(IF(I7="","",IF(I7=1,IF(F7>0,F7/100,100/ABS(F7)),-1)),"") -> -1 | M7: =IFERROR(IF(J7="","",IF(J7=1,IF(G7>0,G7/100,100/ABS(G7)),-1)),"") -> -1 | N7: =IFERROR(IF(K7="","",IF(K7=1,IF(H7>0,H7/100,100/ABS(H7)),-1)),"") -> -1 | O7: =IF(COUNT(I7,J7,K7,W7)=0,"",SUM(L7,M7,N7,X7)) -> -4 | V7: -280 | W7: 0 | X7: =IFERROR(IF(W7="","",IF(W7=1,IF(V9>0,V9/100,100/ABS(V9)),-1)),"") -> -1
A8: 46259 | B8: Miguel Vargas | C8: CWS | D8: 160.2 | F8: 446 | G8: 322 | H8: 1680 | I8: 0 | J8: 1 | K8: 0 | L8: =IFERROR(IF(I8="","",IF(I8=1,IF(F8>0,F8/100,100/ABS(F8)),-1)),"") -> -1 | M8: =IFERROR(IF(J8="","",IF(J8=1,IF(G8>0,G8/100,100/ABS(G8)),-1)),"") -> 3.22 | N8: =IFERROR(IF(K8="","",IF(K8=1,IF(H8>0,H8/100,100/ABS(H8)),-1)),"") -> -1 | O8: =IF(COUNT(I8,J8,K8,W8)=0,"",SUM(L8,M8,N8,X8)) -> 1.7786592 | V8: -179 | W8: 1 | X8: =IFERROR(IF(W8="","",IF(W8=1,IF(V8>0,V8/100,100/ABS(V8)),-1)),"") -> 0.55865922
A9: 46259 | B9: Jordan Walker | C9: STL | D9: 158.5 | F9: 620 | G9: 260 | H9: 1260 | I9: 0 | J9: 0 | K9: 0 | L9: =IFERROR(IF(I9="","",IF(I9=1,IF(F9>0,F9/100,100/ABS(F9)),-1)),"") -> -1 | M9: =IFERROR(IF(J9="","",IF(J9=1,IF(G9>0,G9/100,100/ABS(G9)),-1)),"") -> -1 | N9: =IFERROR(IF(K9="","",IF(K9=1,IF(H9>0,H9/100,100/ABS(H9)),-1)),"") -> -1 | O9: =IF(COUNT(I9,J9,K9,W9)=0,"",SUM(L9,M9,N9,X9)) -> -4 | V9: -219 | W9: 0 | X9: =IFERROR(IF(W9="","",IF(W9=1,IF(#REF!>0,#REF!/100,100/ABS(#REF!)),-1)),"") -> -1
A10: 46259 | B10: Shohei Ohtani | C10: LAD | D10: 157.5 | F10: 233 | G10: 210 | H10: 900 | I10: 0 | J10: 0 | K10: 0 | L10: =IFERROR(IF(I10="","",IF(I10=1,IF(F10>0,F10/100,100/ABS(F10)),-1)),"") -> -1 | M10: =IFERROR(IF(J10="","",IF(J10=1,IF(G10>0,G10/100,100/ABS(G10)),-1)),"") -> -1 | N10: =IFERROR(IF(K10="","",IF(K10=1,IF(H10>0,H10/100,100/ABS(H10)),-1)),"") -> -1 | O10: =IF(COUNT(I10,J10,K10,W10)=0,"",SUM(L10,M10,N10,X10)) -> -2.6108949 | V10: -257 | W10: 1 | X10: =IFERROR(IF(W10="","",IF(W10=1,IF(V10>0,V10/100,100/ABS(V10)),-1)),"") -> 0.38910506
A11: 46259 | B11: Fernando Tatis Jr. | C11: SDP | D11: 157.2 | F11: 471 | G11: 207 | H11: 930 | I11: 0 | J11: 0 | K11: 0 | L11: =IFERROR(IF(I11="","",IF(I11=1,IF(F11>0,F11/100,100/ABS(F11)),-1)),"") -> -1 | M11: =IFERROR(IF(J11="","",IF(J11=1,IF(G11>0,G11/100,100/ABS(G11)),-1)),"") -> -1 | N11: =IFERROR(IF(K11="","",IF(K11=1,IF(H11>0,H11/100,100/ABS(H11)),-1)),"") -> -1 | O11: =IF(COUNT(I11,J11,K11,W11)=0,"",SUM(L11,M11,N11,X11)) -> -2.6226415 | V11: -265 | W11: 1 | X11: =IFERROR(IF(W11="","",IF(W11=1,IF(V11>0,V11/100,100/ABS(V11)),-1)),"") -> 0.37735849
A12: 46259 | B12: Jake Bauers | C12: MIL | D12: 156.9 | F12: 496 | G12: 303 | H12: 1400 | I12: 0 | J12: 0 | K12: 0 | L12: =IFERROR(IF(I12="","",IF(I12=1,IF(F12>0,F12/100,100/ABS(F12)),-1)),"") -> -1 | M12: =IFERROR(IF(J12="","",IF(J12=1,IF(G12>0,G12/100,100/ABS(G12)),-1)),"") -> -1 | N12: =IFERROR(IF(K12="","",IF(K12=1,IF(H12>0,H12/100,100/ABS(H12)),-1)),"") -> -1 | O12: =IF(COUNT(I12,J12,K12,W12)=0,"",SUM(L12,M12,N12,X12)) -> -4 | V12: -184 | W12: 0 | X12: =IFERROR(IF(W12="","",IF(W12=1,IF(V12>0,V12/100,100/ABS(V12)),-1)),"") -> -1
A13: 46259 | B13: Corey Seager | C13: TEX | D13: 155 | F13: 485 | G13: 290 | H13: 1380 | I13: 0 | J13: 0 | K13: 0 | L13: =IFERROR(IF(I13="","",IF(I13=1,IF(F13>0,F13/100,100/ABS(F13)),-1)),"") -> -1 | M13: =IFERROR(IF(J13="","",IF(J13=1,IF(G13>0,G13/100,100/ABS(G13)),-1)),"") -> -1 | N13: =IFERROR(IF(K13="","",IF(K13=1,IF(H13>0,H13/100,100/ABS(H13)),-1)),"") -> -1 | O13: =IF(COUNT(I13,J13,K13,W13)=0,"",SUM(L13,M13,N13,X13)) -> -4 | V13: -189 | W13: 0 | X13: =IFERROR(IF(W13="","",IF(W13=1,IF(V13>0,V13/100,100/ABS(V13)),-1)),"") -> -1
A14: 46259 | B14: Junior Caminero | C14: TBR | D14: 153.1 | F14: 349 | G14: 227 | H14: 1000 | I14: 0 | J14: 1 | K14: 0 | L14: =IFERROR(IF(I14="","",IF(I14=1,IF(F14>0,F14/100,100/ABS(F14)),-1)),"") -> -1 | M14: =IFERROR(IF(J14="","",IF(J14=1,IF(G14>0,G14/100,100/ABS(G14)),-1)),"") -> 2.27 | N14: =IFERROR(IF(K14="","",IF(K14=1,IF(H14>0,H14/100,100/ABS(H14)),-1)),"") -> -1 | O14: =IF(COUNT(I14,J14,K14,W14)=0,"",SUM(L14,M14,N14,X14)) -> 0.68666667 | V14: -240 | W14: 1 | X14: =IFERROR(IF(W14="","",IF(W14=1,IF(V14>0,V14/100,100/ABS(V14)),-1)),"") -> 0.41666667
A15: 46259 | B15: Jackson Chourio | C15: MIL | D15: 153.1 | F15: 458 | G15: 185 | H15: 820 | I15: 0 | J15: 0 | K15: 0 | L15: =IFERROR(IF(I15="","",IF(I15=1,IF(F15>0,F15/100,100/ABS(F15)),-1)),"") -> -1 | M15: =IFERROR(IF(J15="","",IF(J15=1,IF(G15>0,G15/100,100/ABS(G15)),-1)),"") -> -1 | N15: =IFERROR(IF(K15="","",IF(K15=1,IF(H15>0,H15/100,100/ABS(H15)),-1)),"") -> -1 | O15: =IF(COUNT(I15,J15,K15,W15)=0,"",SUM(L15,M15,N15,X15)) -> -4 | V15: -281 | W15: 0 | X15: =IFERROR(IF(W15="","",IF(W15=1,IF(V15>0,V15/100,100/ABS(V15)),-1)),"") -> -1
A16: 46259 | B16: Yordan Alvarez | C16: HOU | D16: 152.6 | F16: 221 | G16: 217 | H16: 1000 | I16: 0 | J16: 1 | K16: 1 | L16: =IFERROR(IF(I16="","",IF(I16=1,IF(F16>0,F16/100,100/ABS(F16)),-1)),"") -> -1 | M16: =IFERROR(IF(J16="","",IF(J16=1,IF(G16>0,G16/100,100/ABS(G16)),-1)),"") -> 2.17 | N16: =IFERROR(IF(K16="","",IF(K16=1,IF(H16>0,H16/100,100/ABS(H16)),-1)),"") -> 10 | O16: =IF(COUNT(I16,J16,K16,W16)=0,"",SUM(L16,M16,N16,X16)) -> 11.566825 | V16: -252 | W16: 1 | X16: =IFERROR(IF(W16="","",IF(W16=1,IF(V16>0,V16/100,100/ABS(V16)),-1)),"") -> 0.3968254
A17: 46259 | B17: Isaac Paredes | C17: HOU | D17: 149.1 | F17: 599 | G17: 311 | H17: 1540 | I17: 0 | J17: 0 | K17: 0 | L17: =IFERROR(IF(I17="","",IF(I17=1,IF(F17>0,F17/100,100/ABS(F17)),-1)),"") -> -1 | M17: =IFERROR(IF(J17="","",IF(J17=1,IF(G17>0,G17/100,100/ABS(G17)),-1)),"") -> -1 | N17: =IFERROR(IF(K17="","",IF(K17=1,IF(H17>0,H17/100,100/ABS(H17)),-1)),"") -> -1 | O17: =IF(COUNT(I17,J17,K17,W17)=0,"",SUM(L17,M17,N17,X17)) -> -2.4444444 | V17: -180 | W17: 1 | X17: =IFERROR(IF(W17="","",IF(W17=1,IF(V17>0,V17/100,100/ABS(V17)),-1)),"") -> 0.55555556
A18: 46259 | B18: Henry Bolte | C18: ATH | D18: 148 | F18: 630 | G18: 200 | H18: 890 | I18: 0 | J18: 0 | K18: 0 | L18: =IFERROR(IF(I18="","",IF(I18=1,IF(F18>0,F18/100,100/ABS(F18)),-1)),"") -> -1 | M18: =IFERROR(IF(J18="","",IF(J18=1,IF(G18>0,G18/100,100/ABS(G18)),-1)),"") -> -1 | N18: =IFERROR(IF(K18="","",IF(K18=1,IF(H18>0,H18/100,100/ABS(H18)),-1)),"") -> -1 | O18: =IF(COUNT(I18,J18,K18,W18)=0,"",SUM(L18,M18,N18,X18)) -> -2.6323529 | V18: -272 | W18: 1 | X18: =IFERROR(IF(W18="","",IF(W18=1,IF(V18>0,V18/100,100/ABS(V18)),-1)),"") -> 0.36764706
A19: 46259 | B19: William Contreras | C19: MIL | D19: 147.4 | F19: 554 | G19: 230 | H19: 1020 | I19: 0 | J19: 1 | K19: 1 | L19: =IFERROR(IF(I19="","",IF(I19=1,IF(F19>0,F19/100,100/ABS(F19)),-1)),"") -> -1 | M19: =IFERROR(IF(J19="","",IF(J19=1,IF(G19>0,G19/100,100/ABS(G19)),-1)),"") -> 2.3 | N19: =IFERROR(IF(K19="","",IF(K19=1,IF(H19>0,H19/100,100/ABS(H19)),-1)),"") -> 10.2 | O19: =IF(COUNT(I19,J19,K19,W19)=0,"",SUM(L19,M19,N19,X19)) -> 11.936681 | V19: -229 | W19: 1 | X19: =IFERROR(IF(W19="","",IF(W19=1,IF(V19>0,V19/100,100/ABS(V19)),-1)),"") -> 0.43668122
A20: 46260 | B20: Pete Alonso | C20: BAL | D20: 170.3 | F20: 391 | G20: 183 | H20: 790 | I20: 1 | J20: 0 | K20: 0 | L20: =IFERROR(IF(I20="","",IF(I20=1,IF(F20>0,F20/100,100/ABS(F20)),-1)),"") -> 3.91 | M20: =IFERROR(IF(J20="","",IF(J20=1,IF(G20>0,G20/100,100/ABS(G20)),-1)),"") -> -1 | N20: =IFERROR(IF(K20="","",IF(K20=1,IF(H20>0,H20/100,100/ABS(H20)),-1)),"") -> -1 | O20: =IF(COUNT(I20,J20,K20,W20)=0,"",SUM(L20,M20,N20,X20)) -> 2.2489831 | V20: -295 | W20: 1 | X20: =IFERROR(IF(W20="","",IF(W20=1,IF(V20>0,V20/100,100/ABS(V20)),-1)),"") -> 0.33898305
A21: 46260 | B21: Luis Garcia Jr. | C21: NYY | D21: 168.1 | F21: 280 | G21: 243 | H21: 1120 | I21: 1 | J21: 1 | K21: 1 | L21: =IFERROR(IF(I21="","",IF(I21=1,IF(F21>0,F21/100,100/ABS(F21)),-1)),"") -> 2.8 | M21: =IFERROR(IF(J21="","",IF(J21=1,IF(G21>0,G21/100,100/ABS(G21)),-1)),"") -> 2.43 | N21: =IFERROR(IF(K21="","",IF(K21=1,IF(H21>0,H21/100,100/ABS(H21)),-1)),"") -> 11.2 | O21: =IF(COUNT(I21,J21,K21,W21)=0,"",SUM(L21,M21,N21,X21)) -> 16.868596 | V21: -228 | W21: 1 | X21: =IFERROR(IF(W21="","",IF(W21=1,IF(V21>0,V21/100,100/ABS(V21)),-1)),"") -> 0.43859649
... A24: 46260 | B24: Aec Burleson | C24: STL | D24: 164.1 | F24: 640 | G24: 215 | H24: 1000 | I24: 0 | J24: 0 | K24: 0 | L24: =IFERROR(IF(I24="","",IF(I24=1,IF(F24>0,F24/100,100/ABS(F24)),-1)),"") -> -1 | M24: =IFERROR(IF(J24="","",IF(J24=1,IF(G24>0,G24/100,100/ABS(G24)),-1)),"") -> -1 | N24: =IFERROR(IF(K24="","",IF(K24=1,IF(H24>0,H24/100,100/ABS(H24)),-1)),"") -> -1 | O24: =IF(COUNT(I24,J24,K24,W24)=0,"",SUM(L24,M24,N24,X24)) -> -2.6124031 | V24: -258 | W24: 1 | X24: =IFERROR(IF(W24="","",IF(W24=1,IF(V24>0,V24/100,100/ABS(V24)),-1)),"") -> 0.3875969
A25: 46260 | B25: Willson Contreras | C25: BOS | D25: 164 | F25: 507 | G25: 248 | H25: 1160 | L25: =IFERROR(IF(I25="","",IF(I25=1,IF(F25>0,F25/100,100/ABS(F25)),-1)),"") | M25: =IFERROR(IF(J25="","",IF(J25=1,IF(G25>0,G25/100,100/ABS(G25)),-1)),"") | N25: =IFERROR(IF(K25="","",IF(K25=1,IF(H25>0,H25/100,100/ABS(H25)),-1)),"") | O25: =IF(COUNT(I25,J25,K25,W25)=0,"",SUM(L25,M25,N25,X25)) | V25: -216 | X25: =IFERROR(IF(W25="","",IF(W25=1,IF(V25>0,V25/100,100/ABS(V25)),-1)),"")
A26: 46260 | B26: Max Muncy | C26: LAD | D26: 163.3 | F26: 348 | G26: 319 | H26: 1600 | I26: 0 | J26: 0 | K26: 0 | L26: =IFERROR(IF(I26="","",IF(I26=1,IF(F26>0,F26/100,100/ABS(F26)),-1)),"") -> -1 | M26: =IFERROR(IF(J26="","",IF(J26=1,IF(G26>0,G26/100,100/ABS(G26)),-1)),"") -> -1 | N26: =IFERROR(IF(K26="","",IF(K26=1,IF(H26>0,H26/100,100/ABS(H26)),-1)),"") -> -1 | O26: =IF(COUNT(I26,J26,K26,W26)=0,"",SUM(L26,M26,N26,X26)) -> -4 | V26: -176 | W26: 0 | X26: =IFERROR(IF(W26="","",IF(W26=1,IF(V26>0,V26/100,100/ABS(V26)),-1)),"") -> -1
A27: 46260 | B27: Michael Harris II | C27: ATL | D27: 161.8 | F27: 481 | G27: 243 | H27: 1180 | I27: 0 | J27: 0 | K27: 0 | L27: =IFERROR(IF(I27="","",IF(I27=1,IF(F27>0,F27/100,100/ABS(F27)),-1)),"") -> -1 | M27: =IFERROR(IF(J27="","",IF(J27=1,IF(G27>0,G27/100,100/ABS(G27)),-1)),"") -> -1 | N27: =IFERROR(IF(K27="","",IF(K27=1,IF(H27>0,H27/100,100/ABS(H27)),-1)),"") -> -1 | O27: =IF(COUNT(I27,J27,K27,W27)=0,"",SUM(L27,M27,N27,X27)) -> -4 | V27: -235 | W27: 0 | X27: =IFERROR(IF(W27="","",IF(W27=1,IF(V27>0,V27/100,100/ABS(V27)),-1)),"") -> -1
A28: 46260 | B28: Zach Neto | C28: LAA | D28: 161.3 | F28: 464 | G28: 253 | H28: 1180 | I28: 0 | J28: 0 | K28: 0 | L28: =IFERROR(IF(I28="","",IF(I28=1,IF(F28>0,F28/100,100/ABS(F28)),-1)),"") -> -1 | M28: =IFERROR(IF(J28="","",IF(J28=1,IF(G28>0,G28/100,100/ABS(G28)),-1)),"") -> -1 | N28: =IFERROR(IF(K28="","",IF(K28=1,IF(H28>0,H28/100,100/ABS(H28)),-1)),"") -> -1 | O28: =IF(COUNT(I28,J28,K28,W28)=0,"",SUM(L28,M28,N28,X28)) -> -2.5348837 | V28: -215 | W28: 1 | X28: =IFERROR(IF(W28="","",IF(W28=1,IF(V28>0,V28/100,100/ABS(V28)),-1)),"") -> 0.46511628
A29: 46260 | B29: Junior Caminero | C29: TBR | D29: 160.3 | F29: 400 | G29: 272 | H29: 1280 | I29: 0 | J29: 1 | K29: 0 | L29: =IFERROR(IF(I29="","",IF(I29=1,IF(F29>0,F29/100,100/ABS(F29)),-1)),"") -> -1 | M29: =IFERROR(IF(J29="","",IF(J29=1,IF(G29>0,G29/100,100/ABS(G29)),-1)),"") -> 2.72 | N29: =IFERROR(IF(K29="","",IF(K29=1,IF(H29>0,H29/100,100/ABS(H29)),-1)),"") -> -1 | O29: =IF(COUNT(I29,J29,K29,W29)=0,"",SUM(L29,M29,N29,X29)) -> 1.2250505 | V29: -198 | W29: 1 | X29: =IFERROR(IF(W29="","",IF(W29=1,IF(V29>0,V29/100,100/ABS(V29)),-1)),"") -> 0.50505051
A30: 46260 | B30: Jake Bauers | C30: MIL | D30: 157.9 | F30: 442 | G30: 326 | H30: 1580 | L30: =IFERROR(IF(I30="","",IF(I30=1,IF(F30>0,F30/100,100/ABS(F30)),-1)),"") | M30: =IFERROR(IF(J30="","",IF(J30=1,IF(G30>0,G30/100,100/ABS(G30)),-1)),"") | N30: =IFERROR(IF(K30="","",IF(K30=1,IF(H30>0,H30/100,100/ABS(H30)),-1)),"") | O30: =IF(COUNT(I30,J30,K30,W30)=0,"",SUM(L30,M30,N30,X30)) | V30: -171 | X30: =IFERROR(IF(W30="","",IF(W30=1,IF(V30>0,V30/100,100/ABS(V30)),-1)),"")
A31: 46260 | B31: Fernando Tatis Jr. | C31: SDP | D31: 157.3 | F31: 329 | G31: 179 | H31: 820 | I31: 0 | J31: 0 | K31: 0 | L31: =IFERROR(IF(I31="","",IF(I31=1,IF(F31>0,F31/100,100/ABS(F31)),-1)),"") -> -1 | M31: =IFERROR(IF(J31="","",IF(J31=1,IF(G31>0,G31/100,100/ABS(G31)),-1)),"") -> -1 | N31: =IFERROR(IF(K31="","",IF(K31=1,IF(H31>0,H31/100,100/ABS(H31)),-1)),"") -> -1 | O31: =IF(COUNT(I31,J31,K31,W31)=0,"",SUM(L31,M31,N31,X31)) -> -4 | V31: -309 | W31: 0 | X31: =IFERROR(IF(W31="","",IF(W31=1,IF(V31>0,V31/100,100/ABS(V31)),-1)),"") -> -1
A32: 46260 | B32: Jordan Walker | C32: STL | D32: 156.1 | F32: 522 | G32: 242 | H32: 1140 | I32: 0 | J32: 0 | K32: 0 | L32: =IFERROR(IF(I32="","",IF(I32=1,IF(F32>0,F32/100,100/ABS(F32)),-1)),"") -> -1 | M32: =IFERROR(IF(J32="","",IF(J32=1,IF(G32>0,G32/100,100/ABS(G32)),-1)),"") -> -1 | N32: =IFERROR(IF(K32="","",IF(K32=1,IF(H32>0,H32/100,100/ABS(H32)),-1)),"") -> -1 | O32: =IF(COUNT(I32,J32,K32,W32)=0,"",SUM(L32,M32,N32,X32)) -> -2.5726496 | V32: -234 | W32: 1 | X32: =IFERROR(IF(W32="","",IF(W32=1,IF(V32>0,V32/100,100/ABS(V32)),-1)),"") -> 0.42735043
A33: 46260 | B33: Shohei Ohtani | C33: LAD | D33: 156 | F33: 267 | G33: 200 | H33: 860 | I33: 0 | J33: 1 | K33: 0 | L33: =IFERROR(IF(I33="","",IF(I33=1,IF(F33>0,F33/100,100/ABS(F33)),-1)),"") -> -1 | M33: =IFERROR(IF(J33="","",IF(J33=1,IF(G33>0,G33/100,100/ABS(G33)),-1)),"") -> 2 | N33: =IFERROR(IF(K33="","",IF(K33=1,IF(H33>0,H33/100,100/ABS(H33)),-1)),"") -> -1 | O33: =IF(COUNT(I33,J33,K33,W33)=0,"",SUM(L33,M33,N33,X33)) -> 0.37037037 | V33: -270 | W33: 1 | X33: =IFERROR(IF(W33="","",IF(W33=1,IF(V33>0,V33/100,100/ABS(V33)),-1)),"") -> 0.37037037
A34: 46260 | B34: Brandon Lowe | C34: PIT | D34: 154.6 | F34: 338 | G34: 293 | H34: 1440 | I34: 0 | J34: 0 | K34: 0 | L34: =IFERROR(IF(I34="","",IF(I34=1,IF(F34>0,F34/100,100/ABS(F34)),-1)),"") -> -1 | M34: =IFERROR(IF(J34="","",IF(J34=1,IF(G34>0,G34/100,100/ABS(G34)),-1)),"") -> -1 | N34: =IFERROR(IF(K34="","",IF(K34=1,IF(H34>0,H34/100,100/ABS(H34)),-1)),"") -> -1 | O34: =IF(COUNT(I34,J34,K34,W34)=0,"",SUM(L34,M34,N34,X34)) -> -4 | V34: -193 | W34: 0 | X34: =IFERROR(IF(W34="","",IF(W34=1,IF(V34>0,V34/100,100/ABS(V34)),-1)),"") -> -1
A35: 46261 | B35: Yordan Alvarez | C35: HOU | D35: 182.3 | F35: 248 | G35: 263 | H35: 1360 | L35: =IFERROR(IF(I35="","",IF(I35=1,IF(F35>0,F35/100,100/ABS(F35)),-1)),"") | M35: =IFERROR(IF(J35="","",IF(J35=1,IF(G35>0,G35/100,100/ABS(G35)),-1)),"") | N35: =IFERROR(IF(K35="","",IF(K35=1,IF(H35>0,H35/100,100/ABS(H35)),-1)),"") | O35: =IFERROR(IF(_xlfn.CONCAT(I35,J35,K35)="","",IFERROR(L35,0)+IFERROR(M35,0)+IFERROR(N35,0)),"") | V35: -211 | X35: =IFERROR(IF(W35="","",IF(W35=1,IF(V35>0,V35/100,100/ABS(V35)),-1)),"")
A36: 46261 | B36: Freddie Freeman | C36: LAD | D36: 162.3 | F36: 920 | G36: 292 | H36: 1420 | L36: =IFERROR(IF(I36="","",IF(I36=1,IF(F36>0,F36/100,100/ABS(F36)),-1)),"") | M36: =IFERROR(IF(J36="","",IF(J36=1,IF(G36>0,G36/100,100/ABS(G36)),-1)),"") | N36: =IFERROR(IF(K36="","",IF(K36=1,IF(H36>0,H36/100,100/ABS(H36)),-1)),"") | O36: =IFERROR(IF(_xlfn.CONCAT(I36,J36,K36)="","",IFERROR(L36,0)+IFERROR(M36,0)+IFERROR(N36,0)),"") | V36: -193 | X36: =IFERROR(IF(W36="","",IF(W36=1,IF(V36>0,V36/100,100/ABS(V36)),-1)),"")
A37: 46261 | B37: William Contreras | C37: MIL | D37: 168.1 | F37: 433 | G37: 208 | H37: 950 | L37: =IFERROR(IF(I37="","",IF(I37=1,IF(F37>0,F37/100,100/ABS(F37)),-1)),"") | M37: =IFERROR(IF(J37="","",IF(J37=1,IF(G37>0,G37/100,100/ABS(G37)),-1)),"") | N37: =IFERROR(IF(K37="","",IF(K37=1,IF(H37>0,H37/100,100/ABS(H37)),-1)),"") | O37: =IFERROR(IF(_xlfn.CONCAT(I37,J37,K37)="","",IFERROR(L37,0)+IFERROR(M37,0)+IFERROR(N37,0)),"") | V37: -262 | X37: =IFERROR(IF(W37="","",IF(W37=1,IF(V37>0,V37/100,100/ABS(V37)),-1)),"")
A38: 46261 | B38: Luis Garcia Jr. | C38: NYY | D38: 168.5 | F38: 321 | G38: 224 | H38: 1080 | L38: =IFERROR(IF(I38="","",IF(I38=1,IF(F38>0,F38/100,100/ABS(F38)),-1)),"") | M38: =IFERROR(IF(J38="","",IF(J38=1,IF(G38>0,G38/100,100/ABS(G38)),-1)),"") | N38: =IFERROR(IF(K38="","",IF(K38=1,IF(H38>0,H38/100,100/ABS(H38)),-1)),"") | O38: =IFERROR(IF(_xlfn.CONCAT(I38,J38,K38)="","",IFERROR(L38,0)+IFERROR(M38,0)+IFERROR(N38,0)),"") | V38: -249 | X38: =IFERROR(IF(W38="","",IF(W38=1,IF(V38>0,V38/100,100/ABS(V38)),-1)),"")
A39: 46261 | B39: Jackson Chourio | C39: MIL | D39: 152.4 | F39: 398 | G39: 178 | H39: 770 | L39: =IFERROR(IF(I39="","",IF(I39=1,IF(F39>0,F39/100,100/ABS(F39)),-1)),"") | M39: =IFERROR(IF(J39="","",IF(J39=1,IF(G39>0,G39/100,100/ABS(G39)),-1)),"") | N39: =IFERROR(IF(K39="","",IF(K39=1,IF(H39>0,H39/100,100/ABS(H39)),-1)),"") | O39: =IFERROR(IF(_xlfn.CONCAT(I39,J39,K39)="","",IFERROR(L39,0)+IFERROR(M39,0)+IFERROR(N39,0)),"") | V39: -303 | X39: =IFERROR(IF(W39="","",IF(W39=1,IF(V39>0,V39/100,100/ABS(V39)),-1)),"")
A40: 46261 | B40: Shohei Ohtani | C40: LAD | D40: 152.4 | F40: 474 | G40: 243 | H40: 1100 | L40: =IFERROR(IF(I40="","",IF(I40=1,IF(F40>0,F40/100,100/ABS(F40)),-1)),"") | M40: =IFERROR(IF(J40="","",IF(J40=1,IF(G40>0,G40/100,100/ABS(G40)),-1)),"") | N40: =IFERROR(IF(K40="","",IF(K40=1,IF(H40>0,H40/100,100/ABS(H40)),-1)),"") | O40: =IFERROR(IF(_xlfn.CONCAT(I40,J40,K40)="","",IFERROR(L40,0)+IFERROR(M40,0)+IFERROR(N40,0)),"") | V40: -231 | X40: =IFERROR(IF(W40="","",IF(W40=1,IF(V40>0,V40/100,100/ABS(V40)),-1)),"")
A41: 46261 | B41: Michael Harris II | C41: ATL | D41: 153 | F41: 542 | G41: 285 | H41: 1560 | L41: =IFERROR(IF(I41="","",IF(I41=1,IF(F41>0,F41/100,100/ABS(F41)),-1)),"") | M41: =IFERROR(IF(J41="","",IF(J41=1,IF(G41>0,G41/100,100/ABS(G41)),-1)),"") | N41: =IFERROR(IF(K41="","",IF(K41=1,IF(H41>0,H41/100,100/ABS(H41)),-1)),"") | O41: =IFERROR(IF(_xlfn.CONCAT(I41,J41,K41)="","",IFERROR(L41,0)+IFERROR(M41,0)+IFERROR(N41,0)),"") | V41: -211 | X41: =IFERROR(IF(W41="","",IF(W41=1,IF(V41>0,V41/100,100/ABS(V41)),-1)),"")
A42: 46261 | B42: Boby Witt Jr. | C42: KCR | D42: 151.8 | F42: 376 | G42: 185 | H42: 800 | L42: =IFERROR(IF(I42="","",IF(I42=1,IF(F42>0,F42/100,100/ABS(F42)),-1)),"") | M42: =IFERROR(IF(J42="","",IF(J42=1,IF(G42>0,G42/100,100/ABS(G42)),-1)),"") | N42: =IFERROR(IF(K42="","",IF(K42=1,IF(H42>0,H42/100,100/ABS(H42)),-1)),"") | O42: =IFERROR(IF(_xlfn.CONCAT(I42,J42,K42)="","",IFERROR(L42,0)+IFERROR(M42,0)+IFERROR(N42,0)),"") | V42: -295 | X42: =IFERROR(IF(W42="","",IF(W42=1,IF(V42>0,V42/100,100/ABS(V42)),-1)),"")
...

Sheet Summary
A1: ⚾ Analytic Overview — Summary
A3: Metric | B3: HR Props | C3: 2H Props | D3: 3H Props | E3: 1H Props | F3: Total
A4: Bets placed | B4: =COUNTA('Props Tracker'!I5:I204) -> 28 | C4: =COUNTA('Props Tracker'!J5:J204) -> 28 | D4: =COUNTA('Props Tracker'!K5:K204) -> 28 | E4: =COUNTA('Props Tracker'!W5:W204) -> 28 | F4: =B4+C4+D4+E4 -> 112
A5: Wins | B5: =COUNTIF('Props Tracker'!I5:I204,1) -> 3 | C5: =COUNTIF('Props Tracker'!J5:J204,1) -> 9 | D5: =COUNTIF('Props Tracker'!K5:K204,1) -> 3 | E5: =COUNTIF('Props Tracker'!W5:W204,1) -> 19 | F5: =B5+C5+D5+E5 -> 34
A6: Losses | B6: =COUNTIF('Props Tracker'!I5:I204,0) -> 25 | C6: =COUNTIF('Props Tracker'!J5:J204,0) -> 19 | D6: =COUNTIF('Props Tracker'!K5:K204,0) -> 25 | E6: =COUNTIF('Props Tracker'!W5:W204,0) -> 9 | F6: =B6+C6+D6+E6 -> 78
A7: Win rate | B7: =IFERROR(COUNTIF('Props Tracker'!I5:I204,1)/COUNTA('Props Tracker'!I5:I204),0) -> 0.10714286 | C7: =IFERROR(COUNTIF('Props Tracker'!J5:J204,1)/COUNTA('Props Tracker'!J5:J204),0) -> 0.32142857 | D7: =IFERROR(COUNTIF('Props Tracker'!K5:K204,1)/COUNTA('Props Tracker'!K5:K204),0) -> 0.10714286 | E7: =IFERROR(COUNTIF('Props Tracker'!W5:W204,1)/COUNTA('Props Tracker'!W5:W204),0) -> 0.67857143 | F7: =IFERROR((B5+C5+D5+E5)/(B4+C4+D4+E4),0) -> 0.30357143
A8: Total P&L ($) | B8: =IFERROR(SUM('Props Tracker'!L5:L204),0) -> -13.77 | C8: =IFERROR(SUM('Props Tracker'!M5:M204),0) -> 3.66 | D8: =IFERROR(SUM('Props Tracker'!N5:N204),0) -> 6.4 | E8: =IFERROR(SUM('Props Tracker'!X5:X204),0) -> -0.87557019 | F8: =B8+C8+D8+E8 -> -4.5855702
A9: ROI | B9: =IFERROR(SUM('Props Tracker'!L5:L204)/COUNTA('Props Tracker'!I5:I204),0) -> -0.49178571 | C9: =IFERROR(SUM('Props Tracker'!M5:M204)/COUNTA('Props Tracker'!J5:J204),0) -> 0.13071429 | D9: =IFERROR(SUM('Props Tracker'!N5:N204)/COUNTA('Props Tracker'!K5:K204),0) -> 0.22857143 | E9: =IFERROR(SUM('Props Tracker'!X5:X204)/COUNTA('Props Tracker'!W5:W204),0) -> -0.031270364 | F9: =IFERROR(F8/F4,0) -> -0.040942591
A10: Break even win rate | B10: ='Props Tracker'!S4 -> 17.016449 | C10: ='Props Tracker'!T4 -> 28.938907 | D10: ='Props Tracker'!U4 -> 7.9295154 | E10: ='Props Tracker'!Z4 -> 69.855305
A12: Profit by Model-Score Threshold
A13: Score | B13: HR | E13: 2+H | H13: 3+H | K13: 1+H | N13: Total $
B14: Profit | C14: % Profit | D14: W/B · Win% | E14: Profit | F14: % Profit | G14: W/B · Win% | H14: Profit | I14: % Profit | J14: W/B · Win% | K14: Profit | L14: % Profit | M14: W/B · Win%
A15: 158 | B15: =SUMIFS('Props Tracker'!$L$5:$L$204,'Props Tracker'!$D$5:$D$204,">="&$A15) -> 0.23 | C15: =IF((COUNTIFS('Props Tracker'!$D$5:$D$204,">="&$A15,'Props Tracker'!$I$5:$I$204,1)+COUNTIFS('Props Tracker'!$D$5:$D$204,">="&$A15,'Props Tracker'!$I$5:$I$204,0))=0,"—",B15/(COUNTIFS('Props Tracker'!$D$5:$D$204,">="&$A15,'Props Tracker'!$I$5:$I$204,1)+COUNTIFS('Props Tracker'!$D$5:$D$204,">="&$A15,'Props Tracker'!$I$5:$I$204,0))) -> 0.016428571 | D15: =IF((COUNTIFS('Props Tracker'!$D$5:$D$204,">="&$A15,'Props Tracker'!$I$5:$I$204,1)+COUNTIFS('Props Tracker'!$D$5:$D$204,">="&$A15,'Props Tracker'!$I$5:$I$204,0))=0,"—",COUNTIFS('Props Tracker'!$D$5:$D$204,">="&$A15,'Props Tracker'!$I$5:$I$204,1)&"/"&(COUNTIFS('Props Tracker'!$D$5:$D$204,">="&$A15,'Props Tracker'!$I$5:$I$204,1)+COUNTIFS('Props Tracker'!$D$5:$D$204,">="&$A15,'Props Tracker'!$I$5:$I$204,0))&" "&TEXT(COUNTIFS('Props Tracker'!$D$5:$D$204,">="&$A15,'Props Tracker'!$I$5:$I$204,1)/(COUNTIFS('Props Tracker'!$D$5:$D$204,">="&$A15,'Props Tracker'!$I$5:$I$204,1)+COUNTIFS('Props Tracker'!$D$5:$D$204,">="&$A15,'Props Tracker'!$I$5:$I$204,0)),"0.0%")) -> 3/14 21.4% | E15: =SUMIFS('Props Tracker'!$M$5:$M$204,'Props Tracker'!$D$5:$D$204,">="&$A15) -> 4.92 | F15: =IF((COUNTIFS('Props Tracker'!$D$5:$D$204,">="&$A15,'Props Tracker'!$J$5:$J$204,1)+COUNTIFS('Props Tracker'!$D$5:$D$204,">="&$A15,'Props Tracker'!$J$5:$J$204,0))=0,"—",E15/(COUNTIFS('Props Tracker'!$D$5:$D$204,">="&$A15,'Props Tracker'!$J$5:$J$204,1)+COUNTIFS('Props Tracker'!$D$5:$D$204,">="&$A15,'Props Tracker'!$J$5:$J$204,0))) -> 0.35142857 | G15: =IF((COUNTIFS('Props Tracker'!$D$5:$D$204,">="&$A15,'Props Tracker'!$J$5:$J$204,1)+COUNTIFS('Props Tracker'!$D$5:$D$204,">="&$A15,'Props Tracker'!$J$5:$J$204,0))=0,"—",COUNTIFS('Props Tracker'!$D$5:$D$204,">="&$A15,'Props Tracker'!$J$5:$J$204,1)&"/"&(COUNTIFS('Props Tracker'!$D$5:$D$204,">="&$A15,'Props Tracker'!$J$5:$J$204,1)+COUNTIFS('Props Tracker'!$D$5:$D$204,">="&$A15,'Props Tracker'!$J$5:$J$204,0))&" "&TEXT(COUNTIFS('Props Tracker'!$D$5:$D$204,">="&$A15,'Props Tracker'!$J$5:$J$204,1)/(COUNTIFS('Props Tracker'!$D$5:$D$204,">="&$A15,'Props Tracker'!$J$5:$J$204,1)+COUNTIFS('Props Tracker'!$D$5:$D$204,">="&$A15,'Props Tracker'!$J$5:$J$204,0)),"0.0%")) -> 5/14 35.7% | H15: =SUMIFS('Props Tracker'!$N$5:$N$204,'Props Tracker'!$D$5:$D$204,">="&$A15) -> -1.8 | I15: =IF((COUNTIFS('Props Tracker'!$D$5:$D$204,">="&$A15,'Props Tracker'!$K$5:$K$204,1)+COUNTIFS('Props Tracker'!$D$5:$D$204,">="&$A15,'Props Tracker'!$K$5:$K$204,0))=0,"—",H15/(COUNTIFS('Props Tracker'!$D$5:$D$204,">="&$A15,'Props Tracker'!$K$5:$K$204,1)+COUNTIFS('Props Tracker'!$D$5:$D$204,">="&$A15,'Props Tracker'!$K$5:$K$204,0))) -> -0.12857143 | J15: =IF((COUNTIFS('Props Tracker'!$D$5:$D$204,">="&$A15,'Props Tracker'!$K$5:$K$204,1)+COUNTIFS('Props Tracker'!$D$5:$D$204,">="&$A15,'Props Tracker'!$K$5:$K$204,0))=0,"—",COUNTIFS('Props Tracker'!$D$5:$D$204,">="&$A15,'Props Tracker'!$K$5:$K$204,1)&"/"&(COUNTIFS('Props Tracker'!$D$5:$D$204,">="&$A15,'Props Tracker'!$K$5:$K$204,1)+COUNTIFS('Props Tracker'!$D$5:$D$204,">="&$A15,'Props Tracker'!$K$5:$K$204,0))&" "&TEXT(COUNTIFS('Props Tracker'!$D$5:$D$204,">="&$A15,'Props Tracker'!$K$5:$K$204,1)/(COUNTIFS('Props Tracker'!$D$5:$D$204,">="&$A15,'Props Tracker'!$K$5:$K$204,1)+COUNTIFS('Props Tracker'!$D$5:$D$204,">="&$A15,'Props Tracker'!$K$5:$K$204,0)),"0.0%")) -> 1/14 7.1% | K15: =SUMIFS('Props Tracker'!$X$5:$X$204,'Props Tracker'!$D$5:$D$204,">="&$A15) -> 0.38686956 | L15: =IF((COUNTIFS('Props Tracker'!$D$5:$D$204,">="&$A15,'Props Tracker'!$W$5:$W$204,1)+COUNTIFS('Props Tracker'!$D$5:$D$204,">="&$A15,'Props Tracker'!$W$5:$W$204,0))=0,"—",K15/(COUNTIFS('Props Tracker'!$D$5:$D$204,">="&$A15,'Props Tracker'!$W$5:$W$204,1)+COUNTIFS('Props Tracker'!$D$5:$D$204,">="&$A15,'Props Tracker'!$W$5:$W$204,0))) -> 0.02763354 | M15: =IF((COUNTIFS('Props Tracker'!$D$5:$D$204,">="&$A15,'Props Tracker'!$W$5:$W$204,1)+COUNTIFS('Props Tracker'!$D$5:$D$204,">="&$A15,'Props Tracker'!$W$5:$W$204,0))=0,"—",COUNTIFS('Props Tracker'!$D$5:$D$204,">="&$A15,'Props Tracker'!$W$5:$W$204,1)&"/"&(COUNTIFS('Props Tracker'!$D$5:$D$204,">="&$A15,'Props Tracker'!$W$5:$W$204,1)+COUNTIFS('Props Tracker'!$D$5:$D$204,">="&$A15,'Props Tracker'!$W$5:$W$204,0))&" "&TEXT(COUNTIFS('Props Tracker'!$D$5:$D$204,">="&$A15,'Props Tracker'!$W$5:$W$204,1)/(COUNTIFS('Props Tracker'!$D$5:$D$204,">="&$A15,'Props Tracker'!$W$5:$W$204,1)+COUNTIFS('Props Tracker'!$D$5:$D$204,">="&$A15,'Props Tracker'!$W$5:$W$204,0)),"0.0%")) -> 10/14 71.4% | N15: =SUM(B15,E15,H15,K15) -> 3.7368696
A16: 160 | B16: =SUMIFS('Props Tracker'!$L$5:$L$204,'Props Tracker'!$D$5:$D$204,">="&$A16) -> 1.23 | C16: =IF((COUNTIFS('Props Tracker'!$D$5:$D$204,">="&$A16,'Props Tracker'!$I$5:$I$204,1)+COUNTIFS('Props Tracker'!$D$5:$D$204,">="&$A16,'Props Tracker'!$I$5:$I$204,0))=0,"—",B16/(COUNTIFS('Props Tracker'!$D$5:$D$204,">="&$A16,'Props Tracker'!$I$5:$I$204,1)+COUNTIFS('Props Tracker'!$D$5:$D$204,">="&$A16,'Props Tracker'!$I$5:$I$204,0))) -> 0.094615385 | D16: =IF((COUNTIFS('Props Tracker'!$D$5:$D$204,">="&$A16,'Props Tracker'!$I$5:$I$204,1)+COUNTIFS('Props Tracker'!$D$5:$D$204,">="&$A16,'Props Tracker'!$I$5:$I$204,0))=0,"—",COUNTIFS('Props Tracker'!$D$5:$D$204,">="&$A16,'Props Tracker'!$I$5:$I$204,1)&"/"&(COUNTIFS('Props Tracker'!$D$5:$D$204,">="&$A16,'Props Tracker'!$I$5:$I$204,1)+COUNTIFS('Props Tracker'!$D$5:$D$204,">="&$A16,'Props Tracker'!$I$5:$I$204,0))&" "&TEXT(COUNTIFS('Props Tracker'!$D$5:$D$204,">="&$A16,'Props Tracker'!$I$5:$I$204,1)/(COUNTIFS('Props Tracker'!$D$5:$D$204,">="&$A16,'Props Tracker'!$I$5:$I$204,1)+COUNTIFS('Props Tracker'!$D$5:$D$204,">="&$A16,'Props Tracker'!$I$5:$I$204,0)),"0.0%")) -> 3/13 23.1% | E16: =SUMIFS('Props Tracker'!$M$5:$M$204,'Props Tracker'!$D$5:$D$204,">="&$A16) -> 5.92 | F16: =IF((COUNTIFS('Props Tracker'!$D$5:$D$204,">="&$A16,'Props Tracker'!$J$5:$J$204,1)+COUNTIFS('Props Tracker'!$D$5:$D$204,">="&$A16,'Props Tracker'!$J$5:$J$204,0))=0,"—",E16/(COUNTIFS('Props Tracker'!$D$5:$D$204,">="&$A16,'Props Tracker'!$J$5:$J$204,1)+COUNTIFS('Props Tracker'!$D$5:$D$204,">="&$A16,'Props Tracker'!$J$5:$J$204,0))) -> 0.45538462 | G16: =IF((COUNTIFS('Props Tracker'!$D$5:$D$204,">="&$A16,'Props Tracker'!$J$5:$J$204,1)+COUNTIFS('Props Tracker'!$D$5:$D$204,">="&$A16,'Props Tracker'!$J$5:$J$204,0))=0,"—",COUNTIFS('Props Tracker'!$D$5:$D$204,">="&$A16,'Props Tracker'!$J$5:$J$204,1)&"/"&(COUNTIFS('Props Tracker'!$D$5:$D$204,">="&$A16,'Props Tracker'!$J$5:$J$204,1)+COUNTIFS('Props Tracker'!$D$5:$D$204,">="&$A16,'Props Tracker'!$J$5:$J$204,0))&" "&TEXT(COUNTIFS('Props Tracker'!$D$5:$D$204,">="&$A16,'Props Tracker'!$J$5:$J$204,1)/(COUNTIFS('Props Tracker'!$D$5:$D$204,">="&$A16,'Props Tracker'!$J$5:$J$204,1)+COUNTIFS('Props Tracker'!$D$5:$D$204,">="&$A16,'Props Tracker'!$J$5:$J$204,0)),"0.0%")) -> 5/13 38.5% | H16: =SUMIFS('Props Tracker'!$N$5:$N$204,'Props Tracker'!$D$5:$D$204,">="&$A16) -> -0.8 | I16: =IF((COUNTIFS('Props Tracker'!$D$5:$D$204,">="&$A16,'Props Tracker'!$K$5:$K$204,1)+COUNTIFS('Props Tracker'!$D$5:$D$204,">="&$A16,'Props Tracker'!$K$5:$K$204,0))=0,"—",H16/(COUNTIFS('Props Tracker'!$D$5:$D$204,">="&$A16,'Props Tracker'!$K$5:$K$204,1)+COUNTIFS('Props Tracker'!$D$5:$D$204,">="&$A16,'Props Tracker'!$K$5:$K$204,0))) -> -0.061538462 | J16: =IF((COUNTIFS('Props Tracker'!$D$5:$D$204,">="&$A16,'Props Tracker'!$K$5:$K$204,1)+COUNTIFS('Props Tracker'!$D$5:$D$204,">="&$A16,'Props Tracker'!$K$5:$K$204,0))=0,"—",COUNTIFS('Props Tracker'!$D$5:$D$204,">="&$A16,'Props Tracker'!$K$5:$K$204,1)&"/"&(COUNTIFS('Props Tracker'!$D$5:$D$204,">="&$A16,'Props Tracker'!$K$5:$K$204,1)+COUNTIFS('Props Tracker'!$D$5:$D$204,">="&$A16,'Props Tracker'!$K$5:$K$204,0))&" "&TEXT(COUNTIFS('Props Tracker'!$D$5:$D$204,">="&$A16,'Props Tracker'!$K$5:$K$204,1)/(COUNTIFS('Props Tracker'!$D$5:$D$204,">="&$A16,'Props Tracker'!$K$5:$K$204,1)+COUNTIFS('Props Tracker'!$D$5:$D$204,">="&$A16,'Props Tracker'!$K$5:$K$204,0)),"0.0%")) -> 1/13 7.7% | K16: =SUMIFS('Props Tracker'!$X$5:$X$204,'Props Tracker'!$D$5:$D$204,">="&$A16) -> 1.3868696 | L16: =IF((COUNTIFS('Props Tracker'!$D$5:$D$204,">="&$A16,'Props Tracker'!$W$5:$W$204,1)+COUNTIFS('Props Tracker'!$D$5:$D$204,">="&$A16,'Props Tracker'!$W$5:$W$204,0))=0,"—",K16/(COUNTIFS('Props Tracker'!$D$5:$D$204,">="&$A16,'Props Tracker'!$W$5:$W$204,1)+COUNTIFS('Props Tracker'!$D$5:$D$204,">="&$A16,'Props Tracker'!$W$5:$W$204,0))) -> 0.10668227 | M16: =IF((COUNTIFS('Props Tracker'!$D$5:$D$204,">="&$A16,'Props Tracker'!$W$5:$W$204,1)+COUNTIFS('Props Tracker'!$D$5:$D$204,">="&$A16,'Props Tracker'!$W$5:$W$204,0))=0,"—",COUNTIFS('Props Tracker'!$D$5:$D$204,">="&$A16,'Props Tracker'!$W$5:$W$204,1)&"/"&(COUNTIFS('Props Tracker'!$D$5:$D$204,">="&$A16,'Props Tracker'!$W$5:$W$204,1)+COUNTIFS('Props Tracker'!$D$5:$D$204,">="&$A16,'Props Tracker'!$W$5:$W$204,0))&" "&TEXT(COUNTIFS('Props Tracker'!$D$5:$D$204,">="&$A16,'Props Tracker'!$W$5:$W$204,1)/(COUNTIFS('Props Tracker'!$D$5:$D$204,">="&$A16,'Props Tracker'!$W$5:$W$204,1)+COUNTIFS('Props Tracker'!$D$5:$D$204,">="&$A16,'Props Tracker'!$W$5:$W$204,0)),"0.0%")) -> 10/13 76.9% | N16: =SUM(B16,E16,H16,K16) -> 7.7368696
A17: 164 | B17: =SUMIFS('Props Tracker'!$L$5:$L$204,'Props Tracker'!$D$5:$D$204,">="&$A17) -> 8.23 | C17: =IF((COUNTIFS('Props Tracker'!$D$5:$D$204,">="&$A17,'Props Tracker'!$I$5:$I$204,1)+COUNTIFS('Props Tracker'!$D$5:$D$204,">="&$A17,'Props Tracker'!$I$5:$I$204,0))=0,"—",B17/(COUNTIFS('Props Tracker'!$D$5:$D$204,">="&$A17,'Props Tracker'!$I$5:$I$204,1)+COUNTIFS('Props Tracker'!$D$5:$D$204,">="&$A17,'Props Tracker'!$I$5:$I$204,0))) -> 1.3716667 | D17: =IF((COUNTIFS('Props Tracker'!$D$5:$D$204,">="&$A17,'Props Tracker'!$I$5:$I$204,1)+COUNTIFS('Props Tracker'!$D$5:$D$204,">="&$A17,'Props Tracker'!$I$5:$I$204,0))=0,"—",COUNTIFS('Props Tracker'!$D$5:$D$204,">="&$A17,'Props Tracker'!$I$5:$I$204,1)&"/"&(COUNTIFS('Props Tracker'!$D$5:$D$204,">="&$A17,'Props Tracker'!$I$5:$I$204,1)+COUNTIFS('Props Tracker'!$D$5:$D$204,">="&$A17,'Props Tracker'!$I$5:$I$204,0))&" "&TEXT(COUNTIFS('Props Tracker'!$D$5:$D$204,">="&$A17,'Props Tracker'!$I$5:$I$204,1)/(COUNTIFS('Props Tracker'!$D$5:$D$204,">="&$A17,'Props Tracker'!$I$5:$I$204,1)+COUNTIFS('Props Tracker'!$D$5:$D$204,">="&$A17,'Props Tracker'!$I$5:$I$204,0)),"0.0%")) -> 3/6 50.0% | E17: =SUMIFS('Props Tracker'!$M$5:$M$204,'Props Tracker'!$D$5:$D$204,">="&$A17) -> 4.98 | F17: =IF((COUNTIFS('Props Tracker'!$D$5:$D$204,">="&$A17,'Props Tracker'!$J$5:$J$204,1)+COUNTIFS('Props Tracker'!$D$5:$D$204,">="&$A17,'Props Tracker'!$J$5:$J$204,0))=0,"—",E17/(COUNTIFS('Props Tracker'!$D$5:$D$204,">="&$A17,'Props Tracker'!$J$5:$J$204,1)+COUNTIFS('Props Tracker'!$D$5:$D$204,">="&$A17,'Props Tracker'!$J$5:$J$204,0))) -> 0.83 | G17: =IF((COUNTIFS('Props Tracker'!$D$5:$D$204,">="&$A17,'Props Tracker'!$J$5:$J$204,1)+COUNTIFS('Props Tracker'!$D$5:$D$204,">="&$A17,'Props Tracker'!$J$5:$J$204,0))=0,"—",COUNTIFS('Props Tracker'!$D$5:$D$204,">="&$A17,'Props Tracker'!$J$5:$J$204,1)&"/"&(COUNTIFS('Props Tracker'!$D$5:$D$204,">="&$A17,'Props Tracker'!$J$5:$J$204,1)+COUNTIFS('Props Tracker'!$D$5:$D$204,">="&$A17,'Props Tracker'!$J$5:$J$204,0))&" "&TEXT(COUNTIFS('Props Tracker'!$D$5:$D$204,">="&$A17,'Props Tracker'!$J$5:$J$204,1)/(COUNTIFS('Props Tracker'!$D$5:$D$204,">="&$A17,'Props Tracker'!$J$5:$J$204,1)+COUNTIFS('Props Tracker'!$D$5:$D$204,">="&$A17,'Props Tracker'!$J$5:$J$204,0)),"0.0%")) -> 3/6 50.0% | H17: =SUMIFS('Props Tracker'!$N$5:$N$204,'Props Tracker'!$D$5:$D$204,">="&$A17) -> 6.2 | I17: =IF((COUNTIFS('Props Tracker'!$D$5:$D$204,">="&$A17,'Props Tracker'!$K$5:$K$204,1)+COUNTIFS('Props Tracker'!$D$5:$D$204,">="&$A17,'Props Tracker'!$K$5:$K$204,0))=0,"—",H17/(COUNTIFS('Props Tracker'!$D$5:$D$204,">="&$A17,'Props Tracker'!$K$5:$K$204,1)+COUNTIFS('Props Tracker'!$D$5:$D$204,">="&$A17,'Props Tracker'!$K$5:$K$204,0))) -> 1.0333333 | J17: =IF((COUNTIFS('Props Tracker'!$D$5:$D$204,">="&$A17,'Props Tracker'!$K$5:$K$204,1)+COUNTIFS('Props Tracker'!$D$5:$D$204,">="&$A17,'Props Tracker'!$K$5:$K$204,0))=0,"—",COUNTIFS('Props Tracker'!$D$5:$D$204,">="&$A17,'Props Tracker'!$K$5:$K$204,1)&"/"&(COUNTIFS('Props Tracker'!$D$5:$D$204,">="&$A17,'Props Tracker'!$K$5:$K$204,1)+COUNTIFS('Props Tracker'!$D$5:$D$204,">="&$A17,'Props Tracker'!$K$5:$K$204,0))&" "&TEXT(COUNTIFS('Props Tracker'!$D$5:$D$204,">="&$A17,'Props Tracker'!$K$5:$K$204,1)/(COUNTIFS('Props Tracker'!$D$5:$D$204,">="&$A17,'Props Tracker'!$K$5:$K$204,1)+COUNTIFS('Props Tracker'!$D$5:$D$204,">="&$A17,'Props Tracker'!$K$5:$K$204,0)),"0.0%")) -> 1/6 16.7% | K17: =SUMIFS('Props Tracker'!$X$5:$X$204,'Props Tracker'!$D$5:$D$204,">="&$A17) -> 2.5577433 | L17: =IF((COUNTIFS('Props Tracker'!$D$5:$D$204,">="&$A17,'Props Tracker'!$W$5:$W$204,1)+COUNTIFS('Props Tracker'!$D$5:$D$204,">="&$A17,'Props Tracker'!$W$5:$W$204,0))=0,"—",K17/(COUNTIFS('Props Tracker'!$D$5:$D$204,">="&$A17,'Props Tracker'!$W$5:$W$204,1)+COUNTIFS('Props Tracker'!$D$5:$D$204,">="&$A17,'Props Tracker'!$W$5:$W$204,0))) -> 0.42629054 | M17: =IF((COUNTIFS('Props Tracker'!$D$5:$D$204,">="&$A17,'Props Tracker'!$W$5:$W$204,1)+COUNTIFS('Props Tracker'!$D$5:$D$204,">="&$A17,'Props Tracker'!$W$5:$W$204,0))=0,"—",COUNTIFS('Props Tracker'!$D$5:$D$204,">="&$A17,'Props Tracker'!$W$5:$W$204,1)&"/"&(COUNTIFS('Props Tracker'!$D$5:$D$204,">="&$A17,'Props Tracker'!$W$5:$W$204,1)+COUNTIFS('Props Tracker'!$D$5:$D$204,">="&$A17,'Props Tracker'!$W$5:$W$204,0))&" "&TEXT(COUNTIFS('Props Tracker'!$D$5:$D$204,">="&$A17,'Props Tracker'!$W$5:$W$204,1)/(COUNTIFS('Props Tracker'!$D$5:$D$204,">="&$A17,'Props Tracker'!$W$5:$W$204,1)+COUNTIFS('Props Tracker'!$D$5:$D$204,">="&$A17,'Props Tracker'!$W$5:$W$204,0)),"0.0%")) -> 6/6 100.0% | N17: =SUM(B17,E17,H17,K17) -> 21.967743
A18: 167 | B18: =SUMIFS('Props Tracker'!$L$5:$L$204,'Props Tracker'!$D$5:$D$204,">="&$A18) -> 5.71 | C18: =IF((COUNTIFS('Props Tracker'!$D$5:$D$204,">="&$A18,'Props Tracker'!$I$5:$I$204,1)+COUNTIFS('Props Tracker'!$D$5:$D$204,">="&$A18,'Props Tracker'!$I$5:$I$204,0))=0,"—",B18/(COUNTIFS('Props Tracker'!$D$5:$D$204,">="&$A18,'Props Tracker'!$I$5:$I$204,1)+COUNTIFS('Props Tracker'!$D$5:$D$204,">="&$A18,'Props Tracker'!$I$5:$I$204,0))) -> 1.9033333 | D18: =IF((COUNTIFS('Props Tracker'!$D$5:$D$204,">="&$A18,'Props Tracker'!$I$5:$I$204,1)+COUNTIFS('Props Tracker'!$D$5:$D$204,">="&$A18,'Props Tracker'!$I$5:$I$204,0))=0,"—",COUNTIFS('Props Tracker'!$D$5:$D$204,">="&$A18,'Props Tracker'!$I$5:$I$204,1)&"/"&(COUNTIFS('Props Tracker'!$D$5:$D$204,">="&$A18,'Props Tracker'!$I$5:$I$204,1)+COUNTIFS('Props Tracker'!$D$5:$D$204,">="&$A18,'Props Tracker'!$I$5:$I$204,0))&" "&TEXT(COUNTIFS('Props Tracker'!$D$5:$D$204,">="&$A18,'Props Tracker'!$I$5:$I$204,1)/(COUNTIFS('Props Tracker'!$D$5:$D$204,">="&$A18,'Props Tracker'!$I$5:$I$204,1)+COUNTIFS('Props Tracker'!$D$5:$D$204,">="&$A18,'Props Tracker'!$I$5:$I$204,0)),"0.0%")) -> 2/3 66.7% | E18: =SUMIFS('Props Tracker'!$M$5:$M$204,'Props Tracker'!$D$5:$D$204,">="&$A18) -> 4.19 | F18: =IF((COUNTIFS('Props Tracker'!$D$5:$D$204,">="&$A18,'Props Tracker'!$J$5:$J$204,1)+COUNTIFS('Props Tracker'!$D$5:$D$204,">="&$A18,'Props Tracker'!$J$5:$J$204,0))=0,"—",E18/(COUNTIFS('Props Tracker'!$D$5:$D$204,">="&$A18,'Props Tracker'!$J$5:$J$204,1)+COUNTIFS('Props Tracker'!$D$5:$D$204,">="&$A18,'Props Tracker'!$J$5:$J$204,0))) -> 1.3966667 | G18: =IF((COUNTIFS('Props Tracker'!$D$5:$D$204,">="&$A18,'Props Tracker'!$J$5:$J$204,1)+COUNTIFS('Props Tracker'!$D$5:$D$204,">="&$A18,'Props Tracker'!$J$5:$J$204,0))=0,"—",COUNTIFS('Props Tracker'!$D$5:$D$204,">="&$A18,'Props Tracker'!$J$5:$J$204,1)&"/"&(COUNTIFS('Props Tracker'!$D$5:$D$204,">="&$A18,'Props Tracker'!$J$5:$J$204,1)+COUNTIFS('Props Tracker'!$D$5:$D$204,">="&$A18,'Props Tracker'!$J$5:$J$204,0))&" "&TEXT(COUNTIFS('Props Tracker'!$D$5:$D$204,">="&$A18,'Props Tracker'!$J$5:$J$204,1)/(COUNTIFS('Props Tracker'!$D$5:$D$204,">="&$A18,'Props Tracker'!$J$5:$J$204,1)+COUNTIFS('Props Tracker'!$D$5:$D$204,">="&$A18,'Props Tracker'!$J$5:$J$204,0)),"0.0%")) -> 2/3 66.7% | H18: =SUMIFS('Props Tracker'!$N$5:$N$204,'Props Tracker'!$D$5:$D$204,">="&$A18) -> 9.2 | I18: =IF((COUNTIFS('Props Tracker'!$D$5:$D$204,">="&$A18,'Props Tracker'!$K$5:$K$204,1)+COUNTIFS('Props Tracker'!$D$5:$D$204,">="&$A18,'Props Tracker'!$K$5:$K$204,0))=0,"—",H18/(COUNTIFS('Props Tracker'!$D$5:$D$204,">="&$A18,'Props Tracker'!$K$5:$K$204,1)+COUNTIFS('Props Tracker'!$D$5:$D$204,">="&$A18,'Props Tracker'!$K$5:$K$204,0))) -> 3.0666667 | J18: =IF((COUNTIFS('Props Tracker'!$D$5:$D$204,">="&$A18,'Props Tracker'!$K$5:$K$204,1)+COUNTIFS('Props Tracker'!$D$5:$D$204,">="&$A18,'Props Tracker'!$K$5:$K$204,0))=0,"—",COUNTIFS('Props Tracker'!$D$5:$D$204,">="&$A18,'Props Tracker'!$K$5:$K$204,1)&"/"&(COUNTIFS('Props Tracker'!$D$5:$D$204,">="&$A18,'Props Tracker'!$K$5:$K$204,1)+COUNTIFS('Props Tracker'!$D$5:$D$204,">="&$A18,'Props Tracker'!$K$5:$K$204,0))&" "&TEXT(COUNTIFS('Props Tracker'!$D$5:$D$204,">="&$A18,'Props Tracker'!$K$5:$K$204,1)/(COUNTIFS('Props Tracker'!$D$5:$D$204,">="&$A18,'Props Tracker'!$K$5:$K$204,1)+COUNTIFS('Props Tracker'!$D$5:$D$204,">="&$A18,'Props Tracker'!$K$5:$K$204,0)),"0.0%")) -> 1/3 33.3% | K18: =SUMIFS('Props Tracker'!$X$5:$X$204,'Props Tracker'!$D$5:$D$204,">="&$A18) -> 1.275092 | L18: =IF((COUNTIFS('Props Tracker'!$D$5:$D$204,">="&$A18,'Props Tracker'!$W$5:$W$204,1)+COUNTIFS('Props Tracker'!$D$5:$D$204,">="&$A18,'Props Tracker'!$W$5:$W$204,0))=0,"—",K18/(COUNTIFS('Props Tracker'!$D$5:$D$204,">="&$A18,'Props Tracker'!$W$5:$W$204,1)+COUNTIFS('Props Tracker'!$D$5:$D$204,">="&$A18,'Props Tracker'!$W$5:$W$204,0))) -> 0.42503066 | M18: =IF((COUNTIFS('Props Tracker'!$D$5:$D$204,">="&$A18,'Props Tracker'!$W$5:$W$204,1)+COUNTIFS('Props Tracker'!$D$5:$D$204,">="&$A18,'Props Tracker'!$W$5:$W$204,0))=0,"—",COUNTIFS('Props Tracker'!$D$5:$D$204,">="&$A18,'Props Tracker'!$W$5:$W$204,1)&"/"&(COUNTIFS('Props Tracker'!$D$5:$D$204,">="&$A18,'Props Tracker'!$W$5:$W$204,1)+COUNTIFS('Props Tracker'!$D$5:$D$204,">="&$A18,'Props Tracker'!$W$5:$W$204,0))&" "&TEXT(COUNTIFS('Props Tracker'!$D$5:$D$204,">="&$A18,'Props Tracker'!$W$5:$W$204,1)/(COUNTIFS('Props Tracker'!$D$5:$D$204,">="&$A18,'Props Tracker'!$W$5:$W$204,1)+COUNTIFS('Props Tracker'!$D$5:$D$204,">="&$A18,'Props Tracker'!$W$5:$W$204,0)),"0.0%")) -> 3/3 100.0% | N18: =SUM(B18,E18,H18,K18) -> 20.375092
A19: 170 | B19: =SUMIFS('Props Tracker'!$L$5:$L$204,'Props Tracker'!$D$5:$D$204,">="&$A19) -> 2.91 | C19: =IF((COUNTIFS('Props Tracker'!$D$5:$D$204,">="&$A19,'Props Tracker'!$I$5:$I$204,1)+COUNTIFS('Props Tracker'!$D$5:$D$204,">="&$A19,'Props Tracker'!$I$5:$I$204,0))=0,"—",B19/(COUNTIFS('Props Tracker'!$D$5:$D$204,">="&$A19,'Props Tracker'!$I$5:$I$204,1)+COUNTIFS('Props Tracker'!$D$5:$D$204,">="&$A19,'Props Tracker'!$I$5:$I$204,0))) -> 1.455 | D19: =IF((COUNTIFS('Props Tracker'!$D$5:$D$204,">="&$A19,'Props Tracker'!$I$5:$I$204,1)+COUNTIFS('Props Tracker'!$D$5:$D$204,">="&$A19,'Props Tracker'!$I$5:$I$204,0))=0,"—",COUNTIFS('Props Tracker'!$D$5:$D$204,">="&$A19,'Props Tracker'!$I$5:$I$204,1)&"/"&(COUNTIFS('Props Tracker'!$D$5:$D$204,">="&$A19,'Props Tracker'!$I$5:$I$204,1)+COUNTIFS('Props Tracker'!$D$5:$D$204,">="&$A19,'Props Tracker'!$I$5:$I$204,0))&" "&TEXT(COUNTIFS('Props Tracker'!$D$5:$D$204,">="&$A19,'Props Tracker'!$I$5:$I$204,1)/(COUNTIFS('Props Tracker'!$D$5:$D$204,">="&$A19,'Props Tracker'!$I$5:$I$204,1)+COUNTIFS('Props Tracker'!$D$5:$D$204,">="&$A19,'Props Tracker'!$I$5:$I$204,0)),"0.0%")) -> 1/2 50.0% | E19: =SUMIFS('Props Tracker'!$M$5:$M$204,'Props Tracker'!$D$5:$D$204,">="&$A19) -> 1.76 | F19: =IF((COUNTIFS('Props Tracker'!$D$5:$D$204,">="&$A19,'Props Tracker'!$J$5:$J$204,1)+COUNTIFS('Props Tracker'!$D$5:$D$204,">="&$A19,'Props Tracker'!$J$5:$J$204,0))=0,"—",E19/(COUNTIFS('Props Tracker'!$D$5:$D$204,">="&$A19,'Props Tracker'!$J$5:$J$204,1)+COUNTIFS('Props Tracker'!$D$5:$D$204,">="&$A19,'Props Tracker'!$J$5:$J$204,0))) -> 0.88 | G19: =IF((COUNTIFS('Props Tracker'!$D$5:$D$204,">="&$A19,'Props Tracker'!$J$5:$J$204,1)+COUNTIFS('Props Tracker'!$D$5:$D$204,">="&$A19,'Props Tracker'!$J$5:$J$204,0))=0,"—",COUNTIFS('Props Tracker'!$D$5:$D$204,">="&$A19,'Props Tracker'!$J$5:$J$204,1)&"/"&(COUNTIFS('Props Tracker'!$D$5:$D$204,">="&$A19,'Props Tracker'!$J$5:$J$204,1)+COUNTIFS('Props Tracker'!$D$5:$D$204,">="&$A19,'Props Tracker'!$J$5:$J$204,0))&" "&TEXT(COUNTIFS('Props Tracker'!$D$5:$D$204,">="&$A19,'Props Tracker'!$J$5:$J$204,1)/(COUNTIFS('Props Tracker'!$D$5:$D$204,">="&$A19,'Props Tracker'!$J$5:$J$204,1)+COUNTIFS('Props Tracker'!$D$5:$D$204,">="&$A19,'Props Tracker'!$J$5:$J$204,0)),"0.0%")) -> 1/2 50.0% | H19: =SUMIFS('Props Tracker'!$N$5:$N$204,'Props Tracker'!$D$5:$D$204,">="&$A19) -> -2 | I19: =IF((COUNTIFS('Props Tracker'!$D$5:$D$204,">="&$A19,'Props Tracker'!$K$5:$K$204,1)+COUNTIFS('Props Tracker'!$D$5:$D$204,">="&$A19,'Props Tracker'!$K$5:$K$204,0))=0,"—",H19/(COUNTIFS('Props Tracker'!$D$5:$D$204,">="&$A19,'Props Tracker'!$K$5:$K$204,1)+COUNTIFS('Props Tracker'!$D$5:$D$204,">="&$A19,'Props Tracker'!$K$5:$K$204,0))) -> -1 | J19: =IF((COUNTIFS('Props Tracker'!$D$5:$D$204,">="&$A19,'Props Tracker'!$K$5:$K$204,1)+COUNTIFS('Props Tracker'!$D$5:$D$204,">="&$A19,'Props Tracker'!$K$5:$K$204,0))=0,"—",COUNTIFS('Props Tracker'!$D$5:$D$204,">="&$A19,'Props Tracker'!$K$5:$K$204,1)&"/"&(COUNTIFS('Props Tracker'!$D$5:$D$204,">="&$A19,'Props Tracker'!$K$5:$K$204,1)+COUNTIFS('Props Tracker'!$D$5:$D$204,">="&$A19,'Props Tracker'!$K$5:$K$204,0))&" "&TEXT(COUNTIFS('Props Tracker'!$D$5:$D$204,">="&$A19,'Props Tracker'!$K$5:$K$204,1)/(COUNTIFS('Props Tracker'!$D$5:$D$204,">="&$A19,'Props Tracker'!$K$5:$K$204,1)+COUNTIFS('Props Tracker'!$D$5:$D$204,">="&$A19,'Props Tracker'!$K$5:$K$204,0)),"0.0%")) -> 0/2 0.0% | K19: =SUMIFS('Props Tracker'!$X$5:$X$204,'Props Tracker'!$D$5:$D$204,">="&$A19) -> 0.83649549 | L19: =IF((COUNTIFS('Props Tracker'!$D$5:$D$204,">="&$A19,'Props Tracker'!$W$5:$W$204,1)+COUNTIFS('Props Tracker'!$D$5:$D$204,">="&$A19,'Props Tracker'!$W$5:$W$204,0))=0,"—",K19/(COUNTIFS('Props Tracker'!$D$5:$D$204,">="&$A19,'Props Tracker'!$W$5:$W$204,1)+COUNTIFS('Props Tracker'!$D$5:$D$204,">="&$A19,'Props Tracker'!$W$5:$W$204,0))) -> 0.41824774 | M19: =IF((COUNTIFS('Props Tracker'!$D$5:$D$204,">="&$A19,'Props Tracker'!$W$5:$W$204,1)+COUNTIFS('Props Tracker'!$D$5:$D$204,">="&$A19,'Props Tracker'!$W$5:$W$204,0))=0,"—",COUNTIFS('Props Tracker'!$D$5:$D$204,">="&$A19,'Props Tracker'!$W$5:$W$204,1)&"/"&(COUNTIFS('Props Tracker'!$D$5:$D$204,">="&$A19,'Props Tracker'!$W$5:$W$204,1)+COUNTIFS('Props Tracker'!$D$5:$D$204,">="&$A19,'Props Tracker'!$W$5:$W$204,0))&" "&TEXT(COUNTIFS('Props Tracker'!$D$5:$D$204,">="&$A19,'Props Tracker'!$W$5:$W$204,1)/(COUNTIFS('Props Tracker'!$D$5:$D$204,">="&$A19,'Props Tracker'!$W$5:$W$204,1)+COUNTIFS('Props Tracker'!$D$5:$D$204,">="&$A19,'Props Tracker'!$W$5:$W$204,0)),"0.0%")) -> 2/2 100.0% | N19: =SUM(B19,E19,H19,K19) -> 3.5064955
A20: 172 | B20: =SUMIFS('Props Tracker'!$L$5:$L$204,'Props Tracker'!$D$5:$D$204,">="&$A20) -> -1 | C20: =IF((COUNTIFS('Props Tracker'!$D$5:$D$204,">="&$A20,'Props Tracker'!$I$5:$I$204,1)+COUNTIFS('Props Tracker'!$D$5:$D$204,">="&$A20,'Props Tracker'!$I$5:$I$204,0))=0,"—",B20/(COUNTIFS('Props Tracker'!$D$5:$D$204,">="&$A20,'Props Tracker'!$I$5:$I$204,1)+COUNTIFS('Props Tracker'!$D$5:$D$204,">="&$A20,'Props Tracker'!$I$5:$I$204,0))) -> -1 | D20: =IF((COUNTIFS('Props Tracker'!$D$5:$D$204,">="&$A20,'Props Tracker'!$I$5:$I$204,1)+COUNTIFS('Props Tracker'!$D$5:$D$204,">="&$A20,'Props Tracker'!$I$5:$I$204,0))=0,"—",COUNTIFS('Props Tracker'!$D$5:$D$204,">="&$A20,'Props Tracker'!$I$5:$I$204,1)&"/"&(COUNTIFS('Props Tracker'!$D$5:$D$204,">="&$A20,'Props Tracker'!$I$5:$I$204,1)+COUNTIFS('Props Tracker'!$D$5:$D$204,">="&$A20,'Props Tracker'!$I$5:$I$204,0))&" "&TEXT(COUNTIFS('Props Tracker'!$D$5:$D$204,">="&$A20,'Props Tracker'!$I$5:$I$204,1)/(COUNTIFS('Props Tracker'!$D$5:$D$204,">="&$A20,'Props Tracker'!$I$5:$I$204,1)+COUNTIFS('Props Tracker'!$D$5:$D$204,">="&$A20,'Props Tracker'!$I$5:$I$204,0)),"0.0%")) -> 0/1 0.0% | E20: =SUMIFS('Props Tracker'!$M$5:$M$204,'Props Tracker'!$D$5:$D$204,">="&$A20) -> 2.76 | F20: =IF((COUNTIFS('Props Tracker'!$D$5:$D$204,">="&$A20,'Props Tracker'!$J$5:$J$204,1)+COUNTIFS('Props Tracker'!$D$5:$D$204,">="&$A20,'Props Tracker'!$J$5:$J$204,0))=0,"—",E20/(COUNTIFS('Props Tracker'!$D$5:$D$204,">="&$A20,'Props Tracker'!$J$5:$J$204,1)+COUNTIFS('Props Tracker'!$D$5:$D$204,">="&$A20,'Props Tracker'!$J$5:$J$204,0))) -> 2.76 | G20: =IF((COUNTIFS('Props Tracker'!$D$5:$D$204,">="&$A20,'Props Tracker'!$J$5:$J$204,1)+COUNTIFS('Props Tracker'!$D$5:$D$204,">="&$A20,'Props Tracker'!$J$5:$J$204,0))=0,"—",COUNTIFS('Props Tracker'!$D$5:$D$204,">="&$A20,'Props Tracker'!$J$5:$J$204,1)&"/"&(COUNTIFS('Props Tracker'!$D$5:$D$204,">="&$A20,'Props Tracker'!$J$5:$J$204,1)+COUNTIFS('Props Tracker'!$D$5:$D$204,">="&$A20,'Props Tracker'!$J$5:$J$204,0))&" "&TEXT(COUNTIFS('Props Tracker'!$D$5:$D$204,">="&$A20,'Props Tracker'!$J$5:$J$204,1)/(COUNTIFS('Props Tracker'!$D$5:$D$204,">="&$A20,'Props Tracker'!$J$5:$J$204,1)+COUNTIFS('Props Tracker'!$D$5:$D$204,">="&$A20,'Props Tracker'!$J$5:$J$204,0)),"0.0%")) -> 1/1 100.0% | H20: =SUMIFS('Props Tracker'!$N$5:$N$204,'Props Tracker'!$D$5:$D$204,">="&$A20) -> -1 | I20: =IF((COUNTIFS('Props Tracker'!$D$5:$D$204,">="&$A20,'Props Tracker'!$K$5:$K$204,1)+COUNTIFS('Props Tracker'!$D$5:$D$204,">="&$A20,'Props Tracker'!$K$5:$K$204,0))=0,"—",H20/(COUNTIFS('Props Tracker'!$D$5:$D$204,">="&$A20,'Props Tracker'!$K$5:$K$204,1)+COUNTIFS('Props Tracker'!$D$5:$D$204,">="&$A20,'Props Tracker'!$K$5:$K$204,0))) -> -1 | J20: =IF((COUNTIFS('Props Tracker'!$D$5:$D$204,">="&$A20,'Props Tracker'!$K$5:$K$204,1)+COUNTIFS('Props Tracker'!$D$5:$D$204,">="&$A20,'Props Tracker'!$K$5:$K$204,0))=0,"—",COUNTIFS('Props Tracker'!$D$5:$D$204,">="&$A20,'Props Tracker'!$K$5:$K$204,1)&"/"&(COUNTIFS('Props Tracker'!$D$5:$D$204,">="&$A20,'Props Tracker'!$K$5:$K$204,1)+COUNTIFS('Props Tracker'!$D$5:$D$204,">="&$A20,'Props Tracker'!$K$5:$K$204,0))&" "&TEXT(COUNTIFS('Props Tracker'!$D$5:$D$204,">="&$A20,'Props Tracker'!$K$5:$K$204,1)/(COUNTIFS('Props Tracker'!$D$5:$D$204,">="&$A20,'Props Tracker'!$K$5:$K$204,1)+COUNTIFS('Props Tracker'!$D$5:$D$204,">="&$A20,'Props Tracker'!$K$5:$K$204,0)),"0.0%")) -> 0/1 0.0% | K20: =SUMIFS('Props Tracker'!$X$5:$X$204,'Props Tracker'!$D$5:$D$204,">="&$A20) -> 0.49751244 | L20: =IF((COUNTIFS('Props Tracker'!$D$5:$D$204,">="&$A20,'Props Tracker'!$W$5:$W$204,1)+COUNTIFS('Props Tracker'!$D$5:$D$204,">="&$A20,'Props Tracker'!$W$5:$W$204,0))=0,"—",K20/(COUNTIFS('Props Tracker'!$D$5:$D$204,">="&$A20,'Props Tracker'!$W$5:$W$204,1)+COUNTIFS('Props Tracker'!$D$5:$D$204,">="&$A20,'Props Tracker'!$W$5:$W$204,0))) -> 0.49751244 | M20: =IF((COUNTIFS('Props Tracker'!$D$5:$D$204,">="&$A20,'Props Tracker'!$W$5:$W$204,1)+COUNTIFS('Props Tracker'!$D$5:$D$204,">="&$A20,'Props Tracker'!$W$5:$W$204,0))=0,"—",COUNTIFS('Props Tracker'!$D$5:$D$204,">="&$A20,'Props Tracker'!$W$5:$W$204,1)&"/"&(COUNTIFS('Props Tracker'!$D$5:$D$204,">="&$A20,'Props Tracker'!$W$5:$W$204,1)+COUNTIFS('Props Tracker'!$D$5:$D$204,">="&$A20,'Props Tracker'!$W$5:$W$204,0))&" "&TEXT(COUNTIFS('Props Tracker'!$D$5:$D$204,">="&$A20,'Props Tracker'!$W$5:$W$204,1)/(COUNTIFS('Props Tracker'!$D$5:$D$204,">="&$A20,'Props Tracker'!$W$5:$W$204,1)+COUNTIFS('Props Tracker'!$D$5:$D$204,">="&$A20,'Props Tracker'!$W$5:$W$204,0)),"0.0%")) -> 1/1 100.0% | N20: =SUM(B20,E20,H20,K20) -> 1.2575124
A21: 174 | B21: =SUMIFS('Props Tracker'!$L$5:$L$204,'Props Tracker'!$D$5:$D$204,">="&$A21) -> 0 | C21: =IF((COUNTIFS('Props Tracker'!$D$5:$D$204,">="&$A21,'Props Tracker'!$I$5:$I$204,1)+COUNTIFS('Props Tracker'!$D$5:$D$204,">="&$A21,'Props Tracker'!$I$5:$I$204,0))=0,"—",B21/(COUNTIFS('Props Tracker'!$D$5:$D$204,">="&$A21,'Props Tracker'!$I$5:$I$204,1)+COUNTIFS('Props Tracker'!$D$5:$D$204,">="&$A21,'Props Tracker'!$I$5:$I$204,0))) -> — | D21: =IF((COUNTIFS('Props Tracker'!$D$5:$D$204,">="&$A21,'Props Tracker'!$I$5:$I$204,1)+COUNTIFS('Props Tracker'!$D$5:$D$204,">="&$A21,'Props Tracker'!$I$5:$I$204,0))=0,"—",COUNTIFS('Props Tracker'!$D$5:$D$204,">="&$A21,'Props Tracker'!$I$5:$I$204,1)&"/"&(COUNTIFS('Props Tracker'!$D$5:$D$204,">="&$A21,'Props Tracker'!$I$5:$I$204,1)+COUNTIFS('Props Tracker'!$D$5:$D$204,">="&$A21,'Props Tracker'!$I$5:$I$204,0))&" "&TEXT(COUNTIFS('Props Tracker'!$D$5:$D$204,">="&$A21,'Props Tracker'!$I$5:$I$204,1)/(COUNTIFS('Props Tracker'!$D$5:$D$204,">="&$A21,'Props Tracker'!$I$5:$I$204,1)+COUNTIFS('Props Tracker'!$D$5:$D$204,">="&$A21,'Props Tracker'!$I$5:$I$204,0)),"0.0%")) -> — | E21: =SUMIFS('Props Tracker'!$M$5:$M$204,'Props Tracker'!$D$5:$D$204,">="&$A21) -> 0 | F21: =IF((COUNTIFS('Props Tracker'!$D$5:$D$204,">="&$A21,'Props Tracker'!$J$5:$J$204,1)+COUNTIFS('Props Tracker'!$D$5:$D$204,">="&$A21,'Props Tracker'!$J$5:$J$204,0))=0,"—",E21/(COUNTIFS('Props Tracker'!$D$5:$D$204,">="&$A21,'Props Tracker'!$J$5:$J$204,1)+COUNTIFS('Props Tracker'!$D$5:$D$204,">="&$A21,'Props Tracker'!$J$5:$J$204,0))) -> — | G21: =IF((COUNTIFS('Props Tracker'!$D$5:$D$204,">="&$A21,'Props Tracker'!$J$5:$J$204,1)+COUNTIFS('Props Tracker'!$D$5:$D$204,">="&$A21,'Props Tracker'!$J$5:$J$204,0))=0,"—",COUNTIFS('Props Tracker'!$D$5:$D$204,">="&$A21,'Props Tracker'!$J$5:$J$204,1)&"/"&(COUNTIFS('Props Tracker'!$D$5:$D$204,">="&$A21,'Props Tracker'!$J$5:$J$204,1)+COUNTIFS('Props Tracker'!$D$5:$D$204,">="&$A21,'Props Tracker'!$J$5:$J$204,0))&" "&TEXT(COUNTIFS('Props Tracker'!$D$5:$D$204,">="&$A21,'Props Tracker'!$J$5:$J$204,1)/(COUNTIFS('Props Tracker'!$D$5:$D$204,">="&$A21,'Props Tracker'!$J$5:$J$204,1)+COUNTIFS('Props Tracker'!$D$5:$D$204,">="&$A21,'Props Tracker'!$J$5:$J$204,0)),"0.0%")) -> — | H21: =SUMIFS('Props Tracker'!$N$5:$N$204,'Props Tracker'!$D$5:$D$204,">="&$A21) -> 0 | I21: =IF((COUNTIFS('Props Tracker'!$D$5:$D$204,">="&$A21,'Props Tracker'!$K$5:$K$204,1)+COUNTIFS('Props Tracker'!$D$5:$D$204,">="&$A21,'Props Tracker'!$K$5:$K$204,0))=0,"—",H21/(COUNTIFS('Props Tracker'!$D$5:$D$204,">="&$A21,'Props Tracker'!$K$5:$K$204,1)+COUNTIFS('Props Tracker'!$D$5:$D$204,">="&$A21,'Props Tracker'!$K$5:$K$204,0))) -> — | J21: =IF((COUNTIFS('Props Tracker'!$D$5:$D$204,">="&$A21,'Props Tracker'!$K$5:$K$204,1)+COUNTIFS('Props Tracker'!$D$5:$D$204,">="&$A21,'Props Tracker'!$K$5:$K$204,0))=0,"—",COUNTIFS('Props Tracker'!$D$5:$D$204,">="&$A21,'Props Tracker'!$K$5:$K$204,1)&"/"&(COUNTIFS('Props Tracker'!$D$5:$D$204,">="&$A21,'Props Tracker'!$K$5:$K$204,1)+COUNTIFS('Props Tracker'!$D$5:$D$204,">="&$A21,'Props Tracker'!$K$5:$K$204,0))&" "&TEXT(COUNTIFS('Props Tracker'!$D$5:$D$204,">="&$A21,'Props Tracker'!$K$5:$K$204,1)/(COUNTIFS('Props Tracker'!$D$5:$D$204,">="&$A21,'Props Tracker'!$K$5:$K$204,1)+COUNTIFS('Props Tracker'!$D$5:$D$204,">="&$A21,'Props Tracker'!$K$5:$K$204,0)),"0.0%")) -> — | K21: =SUMIFS('Props Tracker'!$X$5:$X$204,'Props Tracker'!$D$5:$D$204,">="&$A21) -> 0 | L21: =IF((COUNTIFS('Props Tracker'!$D$5:$D$204,">="&$A21,'Props Tracker'!$W$5:$W$204,1)+COUNTIFS('Props Tracker'!$D$5:$D$204,">="&$A21,'Props Tracker'!$W$5:$W$204,0))=0,"—",K21/(COUNTIFS('Props Tracker'!$D$5:$D$204,">="&$A21,'Props Tracker'!$W$5:$W$204,1)+COUNTIFS('Props Tracker'!$D$5:$D$204,">="&$A21,'Props Tracker'!$W$5:$W$204,0))) -> — | M21: =IF((COUNTIFS('Props Tracker'!$D$5:$D$204,">="&$A21,'Props Tracker'!$W$5:$W$204,1)+COUNTIFS('Props Tracker'!$D$5:$D$204,">="&$A21,'Props Tracker'!$W$5:$W$204,0))=0,"—",COUNTIFS('Props Tracker'!$D$5:$D$204,">="&$A21,'Props Tracker'!$W$5:$W$204,1)&"/"&(COUNTIFS('Props Tracker'!$D$5:$D$204,">="&$A21,'Props Tracker'!$W$5:$W$204,1)+COUNTIFS('Props Tracker'!$D$5:$D$204,">="&$A21,'Props Tracker'!$W$5:$W$204,0))&" "&TEXT(COUNTIFS('Props Tracker'!$D$5:$D$204,">="&$A21,'Props Tracker'!$W$5:$W$204,1)/(COUNTIFS('Props Tracker'!$D$5:$D$204,">="&$A21,'Props Tracker'!$W$5:$W$204,1)+COUNTIFS('Props Tracker'!$D$5:$D$204,">="&$A21,'Props Tracker'!$W$5:$W$204,0)),"0.0%")) -> — | N21: =SUM(B21,E21,H21,K21) -> 0
A22: 176 | B22: =SUMIFS('Props Tracker'!$L$5:$L$204,'Props Tracker'!$D$5:$D$204,">="&$A22) -> 0 | C22: =IF((COUNTIFS('Props Tracker'!$D$5:$D$204,">="&$A22,'Props Tracker'!$I$5:$I$204,1)+COUNTIFS('Props Tracker'!$D$5:$D$204,">="&$A22,'Props Tracker'!$I$5:$I$204,0))=0,"—",B22/(COUNTIFS('Props Tracker'!$D$5:$D$204,">="&$A22,'Props Tracker'!$I$5:$I$204,1)+COUNTIFS('Props Tracker'!$D$5:$D$204,">="&$A22,'Props Tracker'!$I$5:$I$204,0))) -> — | D22: =IF((COUNTIFS('Props Tracker'!$D$5:$D$204,">="&$A22,'Props Tracker'!$I$5:$I$204,1)+COUNTIFS('Props Tracker'!$D$5:$D$204,">="&$A22,'Props Tracker'!$I$5:$I$204,0))=0,"—",COUNTIFS('Props Tracker'!$D$5:$D$204,">="&$A22,'Props Tracker'!$I$5:$I$204,1)&"/"&(COUNTIFS('Props Tracker'!$D$5:$D$204,">="&$A22,'Props Tracker'!$I$5:$I$204,1)+COUNTIFS('Props Tracker'!$D$5:$D$204,">="&$A22,'Props Tracker'!$I$5:$I$204,0))&" "&TEXT(COUNTIFS('Props Tracker'!$D$5:$D$204,">="&$A22,'Props Tracker'!$I$5:$I$204,1)/(COUNTIFS('Props Tracker'!$D$5:$D$204,">="&$A22,'Props Tracker'!$I$5:$I$204,1)+COUNTIFS('Props Tracker'!$D$5:$D$204,">="&$A22,'Props Tracker'!$I$5:$I$204,0)),"0.0%")) -> — | E22: =SUMIFS('Props Tracker'!$M$5:$M$204,'Props Tracker'!$D$5:$D$204,">="&$A22) -> 0 | F22: =IF((COUNTIFS('Props Tracker'!$D$5:$D$204,">="&$A22,'Props Tracker'!$J$5:$J$204,1)+COUNTIFS('Props Tracker'!$D$5:$D$204,">="&$A22,'Props Tracker'!$J$5:$J$204,0))=0,"—",E22/(COUNTIFS('Props Tracker'!$D$5:$D$204,">="&$A22,'Props Tracker'!$J$5:$J$204,1)+COUNTIFS('Props Tracker'!$D$5:$D$204,">="&$A22,'Props Tracker'!$J$5:$J$204,0))) -> — | G22: =IF((COUNTIFS('Props Tracker'!$D$5:$D$204,">="&$A22,'Props Tracker'!$J$5:$J$204,1)+COUNTIFS('Props Tracker'!$D$5:$D$204,">="&$A22,'Props Tracker'!$J$5:$J$204,0))=0,"—",COUNTIFS('Props Tracker'!$D$5:$D$204,">="&$A22,'Props Tracker'!$J$5:$J$204,1)&"/"&(COUNTIFS('Props Tracker'!$D$5:$D$204,">="&$A22,'Props Tracker'!$J$5:$J$204,1)+COUNTIFS('Props Tracker'!$D$5:$D$204,">="&$A22,'Props Tracker'!$J$5:$J$204,0))&" "&TEXT(COUNTIFS('Props Tracker'!$D$5:$D$204,">="&$A22,'Props Tracker'!$J$5:$J$204,1)/(COUNTIFS('Props Tracker'!$D$5:$D$204,">="&$A22,'Props Tracker'!$J$5:$J$204,1)+COUNTIFS('Props Tracker'!$D$5:$D$204,">="&$A22,'Props Tracker'!$J$5:$J$204,0)),"0.0%")) -> — | H22: =SUMIFS('Props Tracker'!$N$5:$N$204,'Props Tracker'!$D$5:$D$204,">="&$A22) -> 0 | I22: =IF((COUNTIFS('Props Tracker'!$D$5:$D$204,">="&$A22,'Props Tracker'!$K$5:$K$204,1)+COUNTIFS('Props Tracker'!$D$5:$D$204,">="&$A22,'Props Tracker'!$K$5:$K$204,0))=0,"—",H22/(COUNTIFS('Props Tracker'!$D$5:$D$204,">="&$A22,'Props Tracker'!$K$5:$K$204,1)+COUNTIFS('Props Tracker'!$D$5:$D$204,">="&$A22,'Props Tracker'!$K$5:$K$204,0))) -> — | J22: =IF((COUNTIFS('Props Tracker'!$D$5:$D$204,">="&$A22,'Props Tracker'!$K$5:$K$204,1)+COUNTIFS('Props Tracker'!$D$5:$D$204,">="&$A22,'Props Tracker'!$K$5:$K$204,0))=0,"—",COUNTIFS('Props Tracker'!$D$5:$D$204,">="&$A22,'Props Tracker'!$K$5:$K$204,1)&"/"&(COUNTIFS('Props Tracker'!$D$5:$D$204,">="&$A22,'Props Tracker'!$K$5:$K$204,1)+COUNTIFS('Props Tracker'!$D$5:$D$204,">="&$A22,'Props Tracker'!$K$5:$K$204,0))&" "&TEXT(COUNTIFS('Props Tracker'!$D$5:$D$204,">="&$A22,'Props Tracker'!$K$5:$K$204,1)/(COUNTIFS('Props Tracker'!$D$5:$D$204,">="&$A22,'Props Tracker'!$K$5:$K$204,1)+COUNTIFS('Props Tracker'!$D$5:$D$204,">="&$A22,'Props Tracker'!$K$5:$K$204,0)),"0.0%")) -> — | K22: =SUMIFS('Props Tracker'!$X$5:$X$204,'Props Tracker'!$D$5:$D$204,">="&$A22) -> 0 | L22: =IF((COUNTIFS('Props Tracker'!$D$5:$D$204,">="&$A22,'Props Tracker'!$W$5:$W$204,1)+COUNTIFS('Props Tracker'!$D$5:$D$204,">="&$A22,'Props Tracker'!$W$5:$W$204,0))=0,"—",K22/(COUNTIFS('Props Tracker'!$D$5:$D$204,">="&$A22,'Props Tracker'!$W$5:$W$204,1)+COUNTIFS('Props Tracker'!$D$5:$D$204,">="&$A22,'Props Tracker'!$W$5:$W$204,0))) -> — | M22: =IF((COUNTIFS('Props Tracker'!$D$5:$D$204,">="&$A22,'Props Tracker'!$W$5:$W$204,1)+COUNTIFS('Props Tracker'!$D$5:$D$204,">="&$A22,'Props Tracker'!$W$5:$W$204,0))=0,"—",COUNTIFS('Props Tracker'!$D$5:$D$204,">="&$A22,'Props Tracker'!$W$5:$W$204,1)&"/"&(COUNTIFS('Props Tracker'!$D$5:$D$204,">="&$A22,'Props Tracker'!$W$5:$W$204,1)+COUNTIFS('Props Tracker'!$D$5:$D$204,">="&$A22,'Props Tracker'!$W$5:$W$204,0))&" "&TEXT(COUNTIFS('Props Tracker'!$D$5:$D$204,">="&$A22,'Props Tracker'!$W$5:$W$204,1)/(COUNTIFS('Props Tracker'!$D$5:$D$204,">="&$A22,'Props Tracker'!$W$5:$W$204,1)+COUNTIFS('Props Tracker'!$D$5:$D$204,">="&$A22,'Props Tracker'!$W$5:$W$204,0)),"0.0%")) -> — | N22: =SUM(B22,E22,H22,K22) -> 0
